execute @s ~ ~ ~ tp @s ~ 60 ~
fill ~-5 62 ~2 ~6 62 ~-2 air

fill ~6 ~ ~ ~-5 ~ ~ planks 5
setblock ~7 ~ ~ dark_oak_stairs 5
setblock ~-6 ~ ~ dark_oak_stairs 4
setblock ~-10 ~ ~ planks 5
setblock ~-11 ~ ~ dark_oak_stairs 4

fill ~8 ~1 ~ ~-8 ~1 ~ planks 5
fill ~-10 ~1 ~ ~-11 ~1 ~ planks 5
fill ~6 ~1 ~1 ~-5 ~1 ~-1 planks 5
setblock ~-9 ~1 ~ dark_oak_stairs 4
setblock ~9 ~1 ~ dark_oak_stairs 5
fill ~6 ~1 ~2 ~-5 ~1 ~2 spruce_stairs 7
fill ~6 ~1 ~-2 ~-5 ~1 ~-2 spruce_stairs 6
setblock ~7 ~1 ~1 spruce_stairs 7
setblock ~7 ~1 ~-1 spruce_stairs 6
fill ~-6 ~1 ~1 ~-8 ~1 ~1 spruce_stairs 7
fill ~-6 ~1 ~-1 ~-8 ~1 ~-1 spruce_stairs 6

setblock ~-1 ~2 ~ stripped_spruce_log
fill ~-1 ~2 ~1 ~-1 ~2 ~2 planks 1
setblock ~-1 ~2 ~-1 spruce_door 2
setblock ~-1 ~2 ~-2 planks 1
fill ~6 ~2 ~-3 ~-5 ~2 ~-3 spruce_stairs 6
fill ~6 ~2 ~3 ~-5 ~2 ~3 spruce_stairs 7
setblock ~-3 ~2 ~1 chest
replaceitem block ~-3 ~2 ~1 slot.container 1 empty_map 
replaceitem block ~-3 ~2 ~1 slot.container 2 feather
replaceitem block ~-3 ~2 ~1 slot.container 3 feather
replaceitem block ~-3 ~2 ~1 slot.container 4 feather
replaceitem block ~-3 ~2 ~1 slot.container 7 feather
replaceitem block ~-3 ~2 ~1 slot.container 9 paper
replaceitem block ~-3 ~2 ~1 slot.container 12 paper
replaceitem block ~-3 ~2 ~1 slot.container 13 paper
replaceitem block ~-3 ~2 ~1 slot.container 14 feather
replaceitem block ~-3 ~2 ~1 slot.container 16 paper
replaceitem block ~-3 ~2 ~1 slot.container 17 feather
replaceitem block ~-3 ~2 ~1 slot.container 21 feather
replaceitem block ~-3 ~2 ~1 slot.container 24 paper
setblock ~ ~2 ~2 spruce_stairs 2
setblock ~3 ~2 ~2 spruce_stairs 2
setblock ~-3 ~2 ~2 spruce_stairs 2
setblock ~ ~2 ~-2 spruce_stairs 3
setblock ~3 ~2 ~-2 spruce_stairs 3
setblock ~-3 ~2 ~-2 spruce_stairs 3
setblock ~4 ~2 ~ stripped_spruce_log
setblock ~6 ~2 ~ chest
setblock ~6 ~2 ~1 chest 4
replaceitem block ~6 ~2 ~ slot.container 1 apple
replaceitem block ~6 ~2 ~ slot.container 6 paper
replaceitem block ~6 ~2 ~ slot.container 11 apple
replaceitem block ~6 ~2 ~ slot.container 22 apple
replaceitem block ~6 ~2 ~1 slot.container 7 compass
replaceitem block ~6 ~2 ~1 slot.container 10 stone_shovel
replaceitem block ~6 ~2 ~1 slot.container 14 wooden_sword
replaceitem block ~6 ~2 ~1 slot.container 21 iron_shovel
fill ~-4 ~2 ~1 ~-4 ~3 ~-1 spruce_stairs 5
fill ~7 ~2 ~1 ~7 ~2 ~-1 planks 1
setblock ~8 ~2 ~ planks 1
setblock ~9 ~2 ~ planks 5
setblock ~10 ~2 ~ dark_oak_stairs 5
fill ~-5 ~2 ~2 ~-5 ~2 ~-2 planks 1
fill ~-6 ~2 ~1 ~-8 ~2 ~-1 planks 1
setblock ~-9 ~2 ~ planks 5
setblock ~-11 ~2 ~ planks 5
setblock ~-10 ~2 ~ fence 5
setblock ~8 ~2 ~-1 spruce_stairs 6
setblock ~8 ~2 ~1 spruce_stairs 7
fill ~1 ~2 ~-2 ~2 ~2 ~-2 planks 1
fill ~1 ~2 ~2 ~2 ~2 ~2 planks 1
fill ~4 ~2 ~-2 ~6 ~2 ~-2 planks 1
fill ~4 ~2 ~2 ~6 ~2 ~2 planks 1
setblock ~-2 ~2 ~-2 planks 1
setblock ~-2 ~2 ~2 planks 1
setblock ~-4 ~2 ~-2 planks 1
setblock ~-4 ~2 ~2 planks 1
fill ~-6 ~2 ~2 ~-7 ~2 ~2 spruce_stairs 7
fill ~-6 ~2 ~-2 ~-7 ~2 ~-2 spruce_stairs 6
setblock ~-8 ~2 ~-2 spruce_stairs 4
setblock ~-8 ~2 ~2 spruce_stairs 4
setblock ~-9 ~2 ~-1 spruce_stairs 4
setblock ~-9 ~2 ~1 spruce_stairs 4
setblock ~-9 ~2 ~-2 wooden_slab 9
setblock ~-9 ~2 ~2 wooden_slab 9
setblock ~7 ~2 ~-2 spruce_stairs 6
setblock ~7 ~2 ~2 spruce_stairs 7

setblock ~-1 ~3 ~ stripped_spruce_log
setblock ~-2 ~3 ~ ladder 4
setblock ~4 ~3 ~ stripped_spruce_log
setblock ~3 ~3 ~ torch 2
setblock ~6 ~3 ~ chest 4
replaceitem block ~6 ~3 ~ slot.container 2 gold_nugget
replaceitem block ~6 ~3 ~ slot.container 3 gold_nugget
replaceitem block ~6 ~3 ~ slot.container 7 feather
replaceitem block ~6 ~3 ~ slot.container 10 feather
replaceitem block ~6 ~3 ~ slot.container 11 gold_ingot
replaceitem block ~6 ~3 ~ slot.container 14 gold_ingot
replaceitem block ~6 ~3 ~ slot.container 15 gold_ingot
replaceitem block ~6 ~3 ~ slot.container 20 gold_ingot
replaceitem block ~6 ~3 ~ slot.container 22 feather
replaceitem block ~6 ~3 ~ slot.container 24 gold_nugget
replaceitem block ~6 ~3 ~ slot.container 25 gold_nugget
setblock ~6 ~3 ~1 tnt
fill ~-1 ~3 ~1 ~-1 ~3 ~3 planks 1
fill ~-1 ~3 ~-2 ~-1 ~3 ~-3 planks 1
fill ~1 ~3 ~2 ~2 ~3 ~3 planks 1
fill ~1 ~3 ~-2 ~2 ~3 ~-3 planks 1
setblock ~ ~3 ~-3 spruce_trapdoor 2
setblock ~3 ~3 ~-3 spruce_trapdoor 2
setblock ~-3 ~3 ~-3 spruce_trapdoor 2
setblock ~ ~3 ~3 spruce_trapdoor 3
setblock ~3 ~3 ~3 spruce_trapdoor 3
setblock ~-3 ~3 ~3 spruce_trapdoor 3
fill ~4 ~3 ~2 ~6 ~3 ~3 planks 1
fill ~4 ~3 ~-2 ~6 ~3 ~-3 planks 1
fill ~-2 ~3 ~-2 ~-2 ~3 ~-3 planks 1
fill ~-2 ~3 ~2 ~-2 ~3 ~3 planks 1
fill ~-2 ~3 ~-2 ~-2 ~3 ~-3 planks 1
fill ~7 ~3 ~-1 ~7 ~3 ~1 spruce_stairs 4
fill ~8 ~3 ~-1 ~8 ~3 ~1 planks 1
fill ~9 ~3 ~ ~10 ~3 ~ planks 1
setblock ~11 ~3 ~ dark_oak_stairs 5
fill ~9 ~3 ~1 ~10 ~3 ~1 spruce_stairs 7
fill ~9 ~3 ~-1 ~10 ~3 ~-1 spruce_stairs 6
setblock ~7 ~3 ~1 planks 1
setblock ~7 ~3 ~-1 planks 1
setblock ~7 ~3 ~2 spruce_stairs 7
setblock ~7 ~3 ~-2 spruce_stairs 6
setblock ~6 ~3 ~3 spruce_stairs 7
setblock ~6 ~3 ~-3 spruce_stairs 6
fill ~-4 ~3 ~-2 ~-5 ~3 ~-3 planks 1
fill ~-4 ~3 ~2 ~-5 ~3 ~3 planks 1
fill ~-5 ~3 ~-1 ~-9 ~3 ~1 planks 5
fill ~-6 ~3 ~2 ~-9 ~3 ~2 planks 5
setblock ~-6 ~3 ~-2 planks 5
setblock ~-6 ~4 ~-2 chest 3
replaceitem block ~-6 ~4 ~-2 slot.container 0 paper
replaceitem block ~-6 ~4 ~-2 slot.container 1 gunpowder 
replaceitem block ~-6 ~4 ~-2 slot.container 13 music_disc_wait
fill ~-7 ~3 ~-2 ~-9 ~3 ~-2 planks 5
fill ~-6 ~3 ~3 ~-9 ~3 ~3 spruce_stairs 7
fill ~-6 ~3 ~-3 ~-9 ~3 ~-3 spruce_stairs 6
setblock ~-10 ~3 ~ fence 5
fill ~-10 ~3 ~1 ~-10 ~3 ~2 spruce_stairs 4
fill ~-10 ~3 ~-1 ~-10 ~3 ~-2 spruce_stairs 4

setblock ~4 ~4 ~1 wooden_slab 5
setblock ~4 ~4 ~-1 wooden_slab 5
fill ~ ~4 ~1 ~ ~4 ~-1 spruce_trapdoor 0
fill ~3 ~4 ~1 ~3 ~4 ~-1 spruce_trapdoor 1
fill ~1 ~4 ~1 ~2 ~4 ~1 spruce_trapdoor 3
fill ~1 ~4 ~-1 ~2 ~4 ~-1 spruce_trapdoor 2
setblock ~-1 ~4 ~ stripped_spruce_log
setblock ~-2 ~4 ~ ladder 4
fill ~-1 ~4 ~3 ~6 ~4 ~2 wooden_slab 5
fill ~-1 ~4 ~-3 ~6 ~4 ~-2 wooden_slab 5
setblock ~4 ~4 ~ stripped_spruce_log
setblock ~-1 ~4 ~1 wooden_slab 5
setblock ~-1 ~4 ~-1 wooden_slab 5
setblock ~-3 ~4 ~ wooden_slab 5
setblock ~-4 ~4 ~ wooden_slab 5
fill ~-2 ~4 ~1 ~-3 ~4 ~2 wooden_slab 5
fill ~-2 ~4 ~-1 ~-3 ~4 ~-2 wooden_slab 5
fill ~-2 ~4 ~3 ~-3 ~4 ~3 planks 5
fill ~-2 ~4 ~-3 ~-3 ~4 ~-3 planks 5
setblock ~4 ~4 ~-1 planks 5
setblock ~4 ~4 ~1 planks 5
fill ~5 ~4 ~1 ~6 ~4 ~1 spruce_trapdoor 3
fill ~5 ~4 ~-1 ~6 ~4 ~-1 spruce_trapdoor 2
setblock ~5 ~4 ~ spruce_trapdoor 0
setblock ~6 ~4 ~ spruce_trapdoor 1
fill ~-4 ~4 ~-1 ~-4 ~4 ~-3 planks 1
fill ~-4 ~4 ~1 ~-4 ~4 ~3 planks 1
setblock ~-5 ~4 ~2 bookshelf
setblock ~-5 ~4 ~-2 jukebox
setblock ~-8 ~4 ~1 spruce_stairs 6
setblock ~-8 ~4 ~-1 spruce_stairs 7
setblock ~-8 ~4 ~ wooden_slab 9
fill ~-5 ~4 ~3 ~-9 ~4 ~3 planks 1
fill ~-5 ~4 ~-3 ~-9 ~4 ~-3 planks 1
fill ~-10 ~4 ~2 ~-10 ~4 ~-2 planks 1
setblock ~-11 ~4 ~ spruce_stairs 4
fill ~7 ~4 ~2 ~7 ~4 ~-2 planks 5
setblock ~8 ~4 ~ stripped_spruce_log
fill ~-5 ~4 ~-4 ~6 ~4 ~-4 spruce_stairs 6
fill ~-5 ~4 ~4 ~6 ~4 ~4 spruce_stairs 7
setblock ~7 ~4 ~-3 planks 1
setblock ~7 ~4 ~3 planks 1
fill ~8 ~4 ~-1 ~8 ~4 ~-2 planks 1
fill ~8 ~4 ~1 ~8 ~4 ~2 planks 1
fill ~9 ~4 ~-1 ~10 ~4 ~1 planks 1
setblock ~11 ~4 ~ planks 5
setblock ~12 ~4 ~ dark_oak_stairs 5
setblock ~11 ~4 ~-1 spruce_stairs 5
setblock ~11 ~4 ~1 spruce_stairs 5
setblock ~8 ~4 ~3 spruce_stairs 7
setblock ~8 ~4 ~-3 spruce_stairs 6
setblock ~9 ~4 ~2 spruce_stairs 7
setblock ~9 ~4 ~-2 spruce_stairs 6
setblock ~10 ~4 ~2 spruce_stairs 7
setblock ~10 ~4 ~-2 spruce_stairs 6

fill ~-1 ~5 ~ ~-1 ~8 ~ stripped_spruce_log
fill ~4 ~5 ~ ~4 ~9 ~ stripped_spruce_log
fill ~3 ~5 ~ ~3 ~9 ~ ladder 4
fill ~8 ~5 ~ ~8 ~8 ~ stripped_spruce_log
setblock ~ ~6 ~ bell 11
fill ~-4 ~5 ~-1 ~-4 ~5 ~-4 planks 1
fill ~-4 ~5 ~1 ~-4 ~5 ~4 planks 1
setblock ~-3 ~5 ~-3 dark_oak_stairs 1
setblock ~-3 ~5 ~3 dark_oak_stairs 1
setblock ~-2 ~5 ~4 fence 5
setblock ~-1 ~5 ~4 dark_oak_fence_gate
setblock ~ ~5 ~4 fence 5
setblock ~1 ~5 ~4 dark_oak_fence_gate
setblock ~2 ~5 ~4 fence 5
setblock ~3 ~5 ~4 dark_oak_fence_gate
setblock ~4 ~5 ~4 fence 5
setblock ~-2 ~5 ~-4 fence 5
setblock ~-1 ~5 ~-4 dark_oak_fence_gate
setblock ~ ~5 ~-4 fence 5
setblock ~1 ~5 ~-4 dark_oak_fence_gate
setblock ~2 ~5 ~-4 fence 5
setblock ~3 ~5 ~-4 dark_oak_fence_gate
setblock ~4 ~5 ~-4 fence 5
fill ~5 ~5 ~4 ~6 ~5 ~4 planks 1
fill ~5 ~5 ~-4 ~6 ~5 ~-4 planks 1
fill ~7 ~5 ~3 ~8 ~5 ~3 planks 1
fill ~7 ~5 ~-3 ~8 ~5 ~-3 planks 1
setblock ~8 ~5 ~2 planks 1
setblock ~8 ~5 ~-2 planks 1
setblock ~8 ~5 ~1 dark_oak_stairs
setblock ~8 ~5 ~-1 dark_oak_stairs
fill ~9 ~5 ~2 ~9 ~5 ~-2 planks 5
fill ~10 ~5 ~1 ~10 ~5 ~-1 planks 5
fill ~11 ~5 ~1 ~11 ~5 ~-1 planks 1
setblock ~12 ~5 ~ planks 5
setblock ~12 ~5 ~-1 spruce_stairs 5
setblock ~12 ~5 ~1 spruce_stairs 5
setblock ~10 ~5 ~2 planks 1
setblock ~10 ~5 ~-2 planks 1
setblock ~9 ~5 ~3 spruce_stairs 7
setblock ~9 ~5 ~-3 spruce_stairs 6
setblock ~7 ~5 ~4 spruce_stairs 5
setblock ~7 ~5 ~-4 spruce_stairs 5
setblock ~-8 ~5 ~-1 lantern
setblock ~-8 ~5 ~ birch_pressure_plate
setblock ~-8 ~5 ~1 skull 1
setblock ~-3 ~5 ~-4 planks 1
setblock ~-3 ~5 ~4 planks 1
fill ~-5 ~5 ~-3 ~-6 ~5 ~-3 planks 1
fill ~-5 ~5 ~3 ~-6 ~5 ~3 planks 1
setblock ~-5 ~5 ~-4 planks 1
setblock ~-5 ~5 ~4 planks 1
fill ~-6 ~5 ~-4 ~-7 ~5 ~-4 spruce_stairs 6
fill ~-6 ~5 ~4 ~-7 ~5 ~4 spruce_stairs 7
setblock ~-7 ~5 ~-3 spruce_stairs 3
setblock ~-7 ~5 ~3 spruce_stairs 2
fill ~-8 ~5 ~3 ~-9 ~5 ~3 planks 1
fill ~-8 ~5 ~-3 ~-9 ~5 ~-3 planks 1
setblock ~-8 ~5 ~4 spruce_stairs 4
setblock ~-8 ~5 ~-4 spruce_stairs 4
fill ~-10 ~5 ~1 ~-10 ~5 ~-1 spruce_stairs 1
setblock ~-11 ~5 ~ planks 1
setblock ~-11 ~5 ~1 spruce_stairs 4
setblock ~-11 ~5 ~-1 spruce_stairs 4
setblock ~-10 ~5 ~2 planks 1
setblock ~-10 ~5 ~-2 planks 1
setblock ~-10 ~5 ~3 spruce_stairs 4
setblock ~-10 ~5 ~-3 spruce_stairs 4

fill ~-4 ~6 ~1 ~-4 ~6 ~2 planks 1
fill ~-4 ~6 ~-1 ~-4 ~6 ~-2 planks 1
setblock ~-4 ~6 ~-3 dark_oak_stairs 1
setblock ~-4 ~6 ~3 dark_oak_stairs 1
fill ~-5 ~6 ~-2 ~-5 ~6 ~2 wooden_slab 13
setblock ~-5 ~6 ~3 planks 5
setblock ~-5 ~6 ~-3 planks 5
setblock ~-3 ~6 ~4 spruce_stairs 1
setblock ~-3 ~6 ~-4 spruce_stairs 1
fill ~-4 ~6 ~4 ~-6 ~6 ~4 planks 1
fill ~-4 ~6 ~-4 ~-6 ~6 ~-4 planks 1
setblock ~-6 ~6 ~3 fence 1
setblock ~-6 ~6 ~-3 fence 1
setblock ~-8 ~6 ~3 fence 1
setblock ~-8 ~6 ~-3 fence 1
fill ~-6 ~7 ~1 ~-6 ~7 ~-1 planks 5
setblock ~-6 ~6 ~1 lantern 1
setblock ~-6 ~6 ~-1 lantern 1
setblock ~-7 ~6 ~-4 spruce_trapdoor 2
setblock ~-7 ~6 ~4 spruce_trapdoor 3
setblock ~-8 ~6 ~4 planks 1
setblock ~-8 ~6 ~-4 planks 1
fill ~-9 ~6 ~-3 ~-10 ~6 ~-3 planks 1
fill ~-9 ~6 ~3 ~-10 ~6 ~3 planks 1
setblock ~-10 ~6 ~2 fence 1
setblock ~-10 ~6 ~-2 fence 1
setblock ~-11 ~6 ~ spruce_trapdoor
setblock ~-11 ~6 ~1 planks 1
setblock ~-11 ~6 ~-1 planks 1
setblock ~-11 ~6 ~2 spruce_stairs 4
setblock ~-11 ~6 ~-2 spruce_stairs 4
setblock ~6 ~6 ~4 spruce_stairs
setblock ~6 ~6 ~-4 spruce_stairs
setblock ~7 ~6 ~3 spruce_stairs
setblock ~7 ~6 ~-3 spruce_stairs
setblock ~7 ~6 ~4 planks 1
setblock ~7 ~6 ~-4 planks 1
fill ~8 ~6 ~3 ~9 ~6 ~3 planks 1
fill ~8 ~6 ~-3 ~9 ~6 ~-3 planks 1
setblock ~10 ~6 ~2 planks 1
setblock ~10 ~6 ~-2 planks 1
setblock ~10 ~7 ~2 lantern
setblock ~10 ~7 ~-2 lantern
setblock ~11 ~6 ~1 planks 1
setblock ~11 ~6 ~-1 planks 1
setblock ~12 ~6 ~1 spruce_stairs 1
setblock ~12 ~6 ~-1 spruce_stairs 1
setblock ~12 ~6 ~ planks 5
setblock ~13 ~6 ~ dark_oak_stairs 5
setblock ~13 ~6 ~-1 fence 5
setblock ~13 ~6 ~1 fence 5
fill ~11 ~7 ~1 ~13 ~7 ~1 fence 5
fill ~11 ~7 ~-1 ~13 ~7 ~-1 fence 5
setblock ~12 ~7 ~ dark_oak_stairs
setblock ~13 ~7 ~ planks 5
setblock ~14 ~7 ~ dark_oak_stairs 5
setblock ~14 ~8 ~ dark_oak_stairs
setblock ~15 ~8 ~ dark_oak_stairs 5

setblock ~-4 ~7 ~ wooden_slab 1
setblock ~-5 ~7 ~ spruce_stairs 1
fill ~-4 ~7 ~1 ~-4 ~7 ~2 fence 5
fill ~-4 ~7 ~-1 ~-4 ~7 ~-2 fence 5
fill ~-7 ~7 ~-2 ~-9 ~7 ~2 wooden_slab 13
setblock ~-7 ~8 ~ grindstone
setblock ~-5 ~7 ~4 spruce_stairs 1
setblock ~-5 ~7 ~-4 spruce_stairs 1
setblock ~-6 ~7 ~2 dark_oak_stairs 1
setblock ~-6 ~7 ~-2 dark_oak_stairs 1
setblock ~-6 ~7 ~3 planks 5
setblock ~-6 ~7 ~-3 planks 5
setblock ~-8 ~7 ~3 planks 5
setblock ~-8 ~7 ~-3 planks 5
setblock ~-7 ~7 ~3 dark_oak_stairs 6
setblock ~-7 ~7 ~-3 dark_oak_stairs 7
fill ~-6 ~7 ~4 ~-8 ~7 ~4 planks 1
fill ~-6 ~7 ~-4 ~-8 ~7 ~-4 planks 1
fill ~-9 ~7 ~3 ~-10 ~7 ~3 planks 1
fill ~-9 ~7 ~-3 ~-10 ~7 ~-3 planks 1
fill ~-10 ~7 ~ ~-11 ~7 ~ wooden_slab 13
setblock ~-10 ~7 ~1 dark_oak_stairs 5
setblock ~-10 ~7 ~-1 dark_oak_stairs 5
setblock ~-10 ~7 ~2 planks 5
setblock ~-10 ~7 ~-2 planks 5
setblock ~-11 ~7 ~1 planks 1
setblock ~-11 ~7 ~-1 planks 1
setblock ~-12 ~7 ~ planks 1
setblock ~-11 ~7 ~2 planks 1
setblock ~-11 ~7 ~-2 planks 1
setblock ~-12 ~7 ~1 spruce_stairs 4
setblock ~-12 ~7 ~-1 spruce_stairs 4

fill ~-6 ~8 ~1 ~-6 ~8 ~-1 planks 1
setblock ~-6 ~8 ~3 planks 1
setblock ~-6 ~9 ~3 lantern
setblock ~-6 ~8 ~-3 planks 1
setblock ~-6 ~9 ~-3 lantern
fill ~-6 ~8 ~-4 ~-8 ~8 ~-4 spruce_stairs 2
fill ~-6 ~8 ~4 ~-8 ~8 ~4 spruce_stairs 3
fill ~-8 ~8 ~3 ~-9 ~8 ~3 fence 5
fill ~-8 ~8 ~-3 ~-9 ~8 ~-3 fence 5
setblock ~-10 ~8 ~3 planks 1
setblock ~-10 ~8 ~-3 planks 1
setblock ~-11 ~8 ~2 planks 1
setblock ~-11 ~8 ~-2 planks 1
setblock ~-11 ~8 ~1 fence 5
setblock ~-11 ~8 ~-1 fence 5
fill ~-12 ~8 ~1 ~-12 ~8 ~-1 fence 5

fill ~-1 ~9 ~1 ~-1 ~9 ~-1 wool
setblock ~-2 ~9 ~ spruce_trapdoor 9
fill ~-1 ~10 ~ ~-1 ~15 ~ stripped_spruce_log
fill ~ ~10 ~1 ~ ~11 ~-1 wool
setblock ~-1 ~10 ~2 wool
setblock ~-1 ~10 ~-2 wool
fill ~ ~11 ~2 ~ ~14 ~2 wool
fill ~ ~11 ~-2 ~ ~14 ~-2 wool
setblock ~ ~12 ~1 wool
fill ~1 ~12 ~ ~1 ~12 ~-1 wool
fill ~1 ~13 ~ ~1 ~13 ~1 wool
setblock ~-1 ~13 ~1 spruce_fence_gate 1
setblock ~-1 ~13 ~-1 spruce_fence_gate 1
setblock ~-1 ~13 ~2 fence 1
setblock ~-1 ~13 ~-2 fence 1
setblock ~ ~13 ~-1 wool
fill ~ ~14 ~1 ~ ~15 ~-1 wool
setblock ~-1 ~15 ~2 wool
setblock ~-1 ~15 ~-2 wool
fill ~-1 ~16 ~1 ~-1 ~16 ~-1 wool
setblock ~-2 ~16 ~ spruce_trapdoor 9
fill ~-2 ~17 ~2 ~-2 ~17 ~-2 planks 1
setblock ~-2 ~17 ~3 spruce_stairs 7
setblock ~-2 ~17 ~-3 spruce_stairs 6
setblock ~-2 ~18 ~2 lantern
setblock ~-2 ~18 ~-2 lantern
setblock ~-1 ~17 ~ stripped_spruce_log
setblock ~-1 ~18 ~ fence 1
setblock ~-1 ~19 ~ wooden_slab 1

fill ~4 ~10 ~1 ~4 ~10 ~-1 wool
fill ~4 ~11 ~ ~4 ~16 ~ stripped_spruce_log
fill ~5 ~11 ~1 ~5 ~13 ~-1 wool
setblock ~4 ~11 ~2 wool
setblock ~4 ~11 ~-2 wool
setblock ~4 ~17 ~ wool
setblock ~4 ~18 ~ stripped_spruce_log
setblock ~4 ~19 ~ wool
fill ~4 ~20 ~ ~4 ~25 ~ stripped_spruce_log
setblock ~4 ~26 ~ wool
fill ~3 ~3 ~ ~3 ~26 ~ ladder 4
setblock ~4 ~12 ~3 wool
setblock ~4 ~12 ~-3 wool
setblock ~5 ~12 ~2 wool
setblock ~5 ~12 ~-2 wool
setblock ~6 ~12 ~1 wool
fill ~6 ~13 ~2 ~6 ~13 ~-1 wool
fill ~6 ~14 ~1 ~6 ~14 ~-2 wool
fill ~5 ~13 ~2 ~5 ~14 ~3 wool
fill ~5 ~13 ~-2 ~5 ~14 ~-3 wool
fill ~5 ~14 ~ ~5 ~16 ~1 wool
setblock ~4 ~14 ~1 spruce_fence_gate 1
setblock ~4 ~14 ~-1 spruce_fence_gate 1
setblock ~4 ~14 ~2 fence 1
setblock ~4 ~14 ~-2 fence 1
fill ~4 ~15 ~3 ~5 ~15 ~3 wool
setblock ~5 ~15 ~2 wool
fill ~4 ~16 ~2 ~5 ~16 ~2 wool
fill ~6 ~15 ~-1 ~6 ~15 ~-2 wool
setblock ~5 ~15 ~-3 wool
fill ~5 ~16 ~-1 ~5 ~16 ~-2 wool
setblock ~4 ~16 ~-3 wool
fill ~4 ~17 ~-1 ~4 ~17 ~-2 wool
setblock ~4 ~17 ~1 wool
fill ~2 ~18 ~-1 ~2 ~18 ~1 spruce_trapdoor 9
fill ~3 ~18 ~1 ~3 ~18 ~3 planks 1
setblock ~3 ~19 ~3 lantern
fill ~3 ~18 ~-1 ~3 ~18 ~-3 planks 1
setblock ~3 ~19 ~-3 lantern
setblock ~3 ~18 ~4 spruce_stairs 7
setblock ~3 ~18 ~-4 spruce_stairs 6
setblock ~4 ~19 ~1 wool
setblock ~4 ~19 ~-1 wool
setblock ~4 ~20 ~2 wool
setblock ~4 ~20 ~-2 wool
fill ~5 ~20 ~1 ~5 ~21 ~-1 wool
setblock ~5 ~21 ~2 wool
setblock ~5 ~21 ~-2 wool
fill ~5 ~22 ~-1 ~5 ~22 ~-2 wool
setblock ~5 ~22 ~2 wool
fill ~6 ~22 ~ ~6 ~22 ~1 wool
setblock ~4 ~23 ~1 spruce_fence_gate 1
setblock ~4 ~23 ~-1 spruce_fence_gate 1
setblock ~4 ~23 ~2 fence 1
setblock ~4 ~23 ~-2 fence 1
setblock ~5 ~23 ~-2 wool
fill ~5 ~23 ~1 ~5 ~23 ~2 wool
fill ~6 ~23 ~ ~6 ~23 ~-1 wool
fill ~5 ~24 ~2 ~5 ~24 ~-2 wool
setblock ~4 ~25 ~2 wool
setblock ~4 ~25 ~-2 wool
fill ~5 ~25 ~1 ~5 ~25 ~-1 wool
fill ~3 ~26 ~1 ~3 ~26 ~3 planks 1
fill ~3 ~26 ~-1 ~3 ~26 ~-3 planks 1
setblock ~3 ~26 ~4 spruce_stairs 7
setblock ~3 ~26 ~-4 spruce_stairs 6
setblock ~3 ~27 ~3 lantern
setblock ~3 ~27 ~-3 lantern
setblock ~4 ~26 ~1 wool
setblock ~4 ~26 ~-1 wool
fill ~3 ~28 ~1 ~5 ~28 ~1 fence 1
fill ~3 ~28 ~-1 ~5 ~28 ~-1 fence 1
setblock ~3 ~28 ~ spruce_fence_gate 1
setblock ~5 ~28 ~ fence 1
fill ~2 ~27 ~1 ~2 ~27 ~-1 spruce_trapdoor 9
fill ~6 ~27 ~1 ~6 ~27 ~-1 spruce_trapdoor 8
fill ~3 ~27 ~1 ~5 ~27 ~1 spruce_stairs 2
fill ~3 ~27 ~-1 ~5 ~27 ~-1 spruce_stairs 3
setblock ~5 ~27 ~ spruce_stairs 0
setblock ~4 ~27 ~ spruce_stairs 0
fill ~3 ~27 ~-2 ~5 ~27 ~-2 spruce_trapdoor 15
fill ~3 ~27 ~2 ~5 ~27 ~2 spruce_trapdoor 14
fill ~5 ~26 ~1 ~5 ~26 ~-1 spruce_trapdoor 4

fill ~8 ~9 ~1 ~8 ~9 ~-1 wool
fill ~8 ~9 ~1 ~8 ~9 ~-1 wool
setblock ~7 ~9 ~ spruce_trapdoor 9
fill ~8 ~10 ~ ~8 ~15 ~ stripped_spruce_log
setblock ~8 ~10 ~2 wool
setblock ~8 ~10 ~-2 wool
fill ~9 ~10 ~1 ~9 ~11 ~-1 wool
setblock ~9 ~11 ~2 wool
setblock ~9 ~11 ~-2 wool
fill ~9 ~12 ~2 ~9 ~13 ~2 wool
fill ~9 ~12 ~-2 ~9 ~13 ~-2 wool
fill ~10 ~12 ~1 ~10 ~13 ~-1 wool
setblock ~8 ~13 ~1 spruce_fence_gate 1
setblock ~8 ~13 ~-1 spruce_fence_gate 1
setblock ~8 ~13 ~2 fence 1
setblock ~8 ~13 ~-2 fence 1
fill ~9 ~14 ~2 ~9 ~14 ~-2 wool
fill ~9 ~15 ~1 ~9 ~15 ~-1 wool
setblock ~8 ~15 ~2 wool
setblock ~8 ~15 ~-2 wool
fill ~8 ~16 ~1 ~8 ~16 ~-1 wool
setblock ~7 ~16 ~ spruce_trapdoor 9
fill ~7 ~17 ~2 ~7 ~17 ~-2 planks 1
setblock ~7 ~17 ~3 spruce_stairs 7
setblock ~7 ~17 ~-3 spruce_stairs 6
setblock ~7 ~18 ~2 lantern
setblock ~7 ~18 ~-2 lantern
setblock ~8 ~17 ~ stripped_spruce_log
setblock ~8 ~18 ~ fence 1
setblock ~8 ~19 ~ wooden_slab 1

summon pillager ~ 62 ~
summon pillager ~ ~5 ~3
summon pillager ~ ~5 ~-3
summon vindicator ~-10 ~8 ~